Workbook

Sheet Сводка
A1: Veligera Capital — pipeline сделок: расчёт доходности
A2: Данные на 24.08.2026. Все суммы в $ млрд. Цена на вторичном рынке — индикативный диапазон фактических сделок; подтверждается по запросу на момент сделки.
A4: Компания | B4: Сектор | C4: Последний раунд | D4: Оценка по последнему раунду | E4: База для вторички | F4: Вторичный рынок: низ | G4: Вторичный рынок: верх | H4: Цена входа (середина) | I4: Горизонт / выход | J4: Оценка на выходе | K4: MOIC (базовый) | L4: Upside (базовый) | M4: IRR (базовый) | N4: MOIC мин. | O4: MOIC макс.
A5: OpenAI | B5: Генеративный ИИ | C5: Раунд $122 млрд (крупнейший частный раунд в истории), закрыт 31.03.2026; со-лид SoftBank | D5: =OpenAI!B6 -> 852 | E5: =OpenAI!B7 -> 852 | F5: =OpenAI!B10 -> 920.16 | G5: =OpenAI!B11 -> 979.8 | H5: =OpenAI!B12 -> 949.98 | I5: 1–2 года (IPO 2026–2027) | J5: =OpenAI!B36 -> 1600 | K5: =OpenAI!B37 -> 1.684246 | L5: =OpenAI!B38 -> 0.68424598 | M5: =OpenAI!B39 -> 0.29778503 | N5: =OpenAI!B40 -> 1.0526537 | O5: =OpenAI!C40 -> 3.2421735
A6: Figure AI | B6: Гуманоидные роботы для промышленности | C6: Series C >$1 млрд, закрыт 16.09.2025; лид Parkway Venture Capital | D6: ='Figure AI'!B6 -> 39 | E6: ='Figure AI'!B7 -> 39 | F6: ='Figure AI'!B10 -> 30 | G6: ='Figure AI'!B11 -> 33 | H6: ='Figure AI'!B12 -> 31.5 | I6: 3–4 года (IPO 2029–2030) | J6: ='Figure AI'!B36 -> 100 | K6: ='Figure AI'!B37 -> 3.1746032 | L6: ='Figure AI'!B38 -> 2.1746032 | M6: ='Figure AI'!B39 -> 0.39104072 | N6: ='Figure AI'!B40 -> 1.2380952 | O6: ='Figure AI'!C40 -> 6.8571429
A7: 1X Technologies | B7: Домашние роботы-помощники | C7: Series C, до $1 млрд, в процессе — оценка $10+ млрд (предыдущий закрытый: Series B $100 млн, январь 2024, лид EQT Ventures) | D7: =1X!B6 -> 10 | E7: =1X!B7 -> 10 | F7: =1X!B10 -> 10.5 | G7: =1X!B11 -> 12 | H7: =1X!B12 -> 11.25 | I7: 2–3 года (IPO 2029) | J7: =1X!B36 -> 40 | K7: =1X!B37 -> 3.5555556 | L7: =1X!B38 -> 2.5555556 | M7: =1X!B39 -> 0.66097459 | N7: =1X!B40 -> 0.88888889 | O7: =1X!C40 -> 9.3333333
A8: Polymarket | B8: Рынки предсказаний | C8: Раунд ~$1 млрд, закрыт в апреле 2026; новые инвесторы D.E. Shaw и G Squared, ICE добавила $600 млн | D8: =Polymarket!B6 -> 15 | E8: =Polymarket!B7 -> 15 | F8: =Polymarket!B10 -> 13.5 | G8: =Polymarket!B11 -> 15 | H8: =Polymarket!B12 -> 14.25 | I8: 2–3 года (IPO 2029 или продажа ICE) | J8: =Polymarket!B36 -> 45 | K8: =Polymarket!B37 -> 3.1578947 | L8: =Polymarket!B38 -> 2.1578947 | M8: =Polymarket!B39 -> 0.58401416 | N8: =Polymarket!B40 -> 1.5438596 | O8: =Polymarket!C40 -> 7.5789474
A9: Kalshi | B9: Рынки предсказаний (США) | C9: Series F $1 млрд, закрыт 07.05.2026; лид Coatue (Sequoia, a16z, IVP, Paradigm, Morgan Stanley, ARK) | D9: =Kalshi!B6 -> 22 | E9: =Kalshi!B7 -> 22 | F9: =Kalshi!B10 -> 30 | G9: =Kalshi!B11 -> 40 | H9: =Kalshi!B12 -> 35 | I9: 1–2 года (IPO 2027–2028) | J9: =Kalshi!B36 -> 75 | K9: =Kalshi!B37 -> 2.1428571 | L9: =Kalshi!B38 -> 1.1428571 | M9: =Kalshi!B39 -> 0.46385011 | N9: =Kalshi!B40 -> 1.1428571 | O9: =Kalshi!C40 -> 4.2857143
A10: Positron AI | B10: Чипы для ИИ (инференс) | C10: Series B $230 млн (переподписан), закрыт 04.02.2026; со-лиды ARENA, Jump Trading, Unless; стратеги QIA и Arm | D10: ='Positron AI'!B6 -> 1 | E10: ='Positron AI'!B7 -> 3.5 | F10: ='Positron AI'!B10 -> 4.5 | G10: ='Positron AI'!B11 -> 5 | H10: ='Positron AI'!B12 -> 4.75 | I10: 3–4 года (IPO / M&A 2029–2030) | J10: ='Positron AI'!B36 -> 24 | K10: ='Positron AI'!B37 -> 5.0526316 | L10: ='Positron AI'!B38 -> 4.0526316 | M10: ='Positron AI'!B39 -> 0.58856518 | N10: ='Positron AI'!B40 -> 1.0526316 | O10: ='Positron AI'!C40 -> 8.4210526
A11: Databricks | B11: Данные и ИИ для корпораций | C11: Стратегический раунд $5 млрд, закрыт 13.08.2026; лид Coatue (спрос ~$15 млрд) | D11: =Databricks!B6 -> 190 | E11: =Databricks!B7 -> 190 | F11: =Databricks!B10 -> 195 | G11: =Databricks!B11 -> 210 | H11: =Databricks!B12 -> 202.5 | I11: 1–2 года (IPO 2027–2028) | J11: =Databricks!B36 -> 425 | K11: =Databricks!B37 -> 2.0987654 | L11: =Databricks!B38 -> 1.0987654 | M11: =Databricks!B39 -> 0.44871165 | N11: =Databricks!B40 -> 0.9382716 | O11: =Databricks!C40 -> 3.0864198
A12: VAST Data | B12: Инфраструктура данных для ИИ | C12: Series F ~$1 млрд ($500 млн первичных + $500 млн выкуп акций), закрыт 22.04.2026; лид Drive Capital, со-лид Access Industries | D12: ='VAST Data'!B6 -> 30 | E12: ='VAST Data'!B7 -> 30 | F12: ='VAST Data'!B10 -> 23 | G12: ='VAST Data'!B11 -> 28 | H12: ='VAST Data'!B12 -> 25.5 | I12: 2–3 года (IPO 2028) | J12: ='VAST Data'!B36 -> 60 | K12: ='VAST Data'!B37 -> 2.3529412 | L12: ='VAST Data'!B38 -> 1.3529412 | M12: ='VAST Data'!B39 -> 0.40813544 | N12: ='VAST Data'!B40 -> 1.1764706 | O12: ='VAST Data'!C40 -> 4.3921569
A13: ByteDance | B13: Соцсети и цифровая реклама | C13: Выкуп акций у сотрудников по $229.50 за акцию, 15.04.2026 (+14.5% к октябрю 2025) — имплайд-оценка $400–450 млрд | D13: =ByteDance!B6 -> 425 | E13: =ByteDance!B7 -> 425 | F13: =ByteDance!B10 -> 590 | G13: =ByteDance!B11 -> 610 | H13: =ByteDance!B12 -> 600 | I13: 1–2 года (выкуп акций / блок-трейд) | J13: =ByteDance!B36 -> 850 | K13: =ByteDance!B37 -> 1.4166667 | L13: =ByteDance!B38 -> 0.41666667 | M13: =ByteDance!B39 -> 0.19023807 | N13: =ByteDance!B40 -> 1 | O13: =ByteDance!C40 -> 2.1
A14: Glean | B14: Корпоративный ИИ-поиск | C14: Series F $150 млн, закрыт 10.06.2025; лид Wellington Management | D14: =Glean!B6 -> 7.2 | E14: =Glean!B7 -> 7.2 | F14: =Glean!B10 -> 6.5 | G14: =Glean!B11 -> 7 | H14: =Glean!B12 -> 6.75 | I14: 2–3 года (IPO 2028) | J14: =Glean!B36 -> 18 | K14: =Glean!B37 -> 2.6666667 | L14: =Glean!B38 -> 1.6666667 | M14: =Glean!B39 -> 0.48042869 | N14: =Glean!B40 -> 1.0666667 | O14: =Glean!C40 -> 5.5555556
A15: Lightmatter | B15: Фотоника для ИИ-дата-центров | C15: Series D $400 млн, закрыт в октябре 2024; лид T. Rowe Price (Fidelity, GV, Viking Global, Lockheed Martin) | D15: =Lightmatter!B6 -> 4.4 | E15: =Lightmatter!B7 -> 4.4 | F15: =Lightmatter!B10 -> 4.4 | G15: =Lightmatter!B11 -> 4.8 | H15: =Lightmatter!B12 -> 4.6 | I15: 3–4 года (IPO / M&A 2029–2030) | J15: =Lightmatter!B36 -> 14 | K15: =Lightmatter!B37 -> 3.0434783 | L15: =Lightmatter!B38 -> 2.0434783 | M15: =Lightmatter!B39 -> 0.37437666 | N15: =Lightmatter!B40 -> 0.86956522 | O15: =Lightmatter!C40 -> 9.7826087
A16: PsiQuantum | B16: Квантовые вычисления | C16: Series E $1.0 млрд, объявлен 10.09.2025; лиды BlackRock, Baillie Gifford, Temasek (с NVentures/NVIDIA, QIA, Macquarie) | D16: =PsiQuantum!B6 -> 7 | E16: =PsiQuantum!B7 -> 7 | F16: =PsiQuantum!B10 -> 7.56 | G16: =PsiQuantum!B11 -> 8.05 | H16: =PsiQuantum!B12 -> 7.805 | I16: 4–5 лет (IPO 2029–2030) | J16: =PsiQuantum!B36 -> 30 | K16: =PsiQuantum!B37 -> 3.8436899 | L16: =PsiQuantum!B38 -> 2.8436899 | M16: =PsiQuantum!B39 -> 0.34878919 | N16: =PsiQuantum!B40 -> 0.96092249 | O16: =PsiQuantum!C40 -> 11.210762
A18: По 1X Technologies и Positron AI последние закрытые раунды устарели, поэтому премия 8–15% считается не от них, а от оценки идущего раунда (1X — Series C ~$10 млрд; Positron — первый транш ~$3.5 млрд).
A19: Базовый сценарий — среднее двух методов (мультипликаторы публичных аналогов и рыночные якоря) от середины диапазона вторичного рынка. MOIC мин./макс. — границы по всем сценариям обоих методов. Разводнение будущих раундов, комиссии и дисконт за неликвидность не учтены. Не является офертой или инвестиционной рекомендацией.

Sheet Методология
A1: Методология и допущения
A3: Оценка по последнему раунду | B3: Post-money оценка последнего ЗАКРЫТОГО раунда финансирования.
A4: Цена на вторичном рынке | B4: Индикативный диапазон: котировки площадок (Forge, Caplight, Nasdaq Private Market) и фактические сделки. Где котировок нет, применяется премия 8–15% к оценке раунда (для 1X и Positron AI — к оценке идущего раунда). Фактическая цена подтверждается по запросу на момент сделки.
A5: Цена входа в расчётах | B5: Середина диапазона вторичного рынка. Расчёт от верхней границы даёт доходность ниже, от нижней — выше.
A6: Метод 1 — мультипликаторы | B6: Оценка на выходе = прогнозная выручка в год выхода x EV/Revenue публичных аналогов.
A7: Метод 2 — рыночные якоря | B7: Оценка на выходе от рыночных сигналов: целевые оценки IPO, раунды в переговорах, оценки прямых конкурентов, размер рынка x целевая доля.
A8: Сценарии | B8: Консервативный / базовый / оптимистичный. В one-pager вынесен базовый сценарий = среднее двух методов.
A9: Метрики | B9: MOIC = оценка на выходе / цена входа; Upside = MOIC − 1; IRR = MOIC^(1/лет) − 1.
A10: Жёлтые ячейки | B10: Ключевые изменяемые допущения (база вторички, премии, выручка, мультипликаторы, оценки-якоря): синий шрифт на жёлтой заливке. Меняйте их — модель пересчитается.
A11: Ограничения | B11: Данные по частным компаниям основаны на публикациях СМИ и трекерах (Bloomberg, CNBC, TechCrunch, Sacra, Forge, Caplight) и могут отличаться от фактических. Разводнение будущих раундов, комиссии и дисконт за неликвидность не учтены. Не оферта и не инвестиционная рекомендация.

Sheet OpenAI
A1: OpenAI
A2: Генеративный ИИ
A4: 1. ЦЕНА
A5: Последний закрытый раунд | B5: Раунд $122 млрд (крупнейший частный раунд в истории), закрыт 31.03.2026; со-лид SoftBank
A6: Оценка по последнему раунду, $ млрд | B6: 852
A7: База для вторичного рынка, $ млрд | B7: 852
A8: Премия к базе — нижняя граница | B8: 0.08
A9: Премия к базе — верхняя граница | B9: 0.15
A10: Цена на вторичном рынке — низ, $ млрд | B10: =B7*(1+B8) -> 920.16
A11: Цена на вторичном рынке — верх, $ млрд | B11: =B7*(1+B9) -> 979.8
A12: Цена входа в расчётах (середина диапазона), $ млрд | B12: =AVERAGE(B10:B11) -> 949.98
A13: Примечание | B13: Диапазон = премия 8–15% к оценке последнего раунда. Тендер сотрудников на $7 млрд закрыт 10.08.2026 по оценке $852 млрд; вторичные сделки перед IPO идут с премией к раунду.
A15: 2. ПУБЛИЧНЫЕ АНАЛОГИ
A16: Компания | B16: Мультипликатор, x | C16: Комментарий
A17: Microsoft | B17: 10.5 | C17: EV/Revenue, авг 2026
A18: NVIDIA | B18: 24.7 | C18: P/S TTM
A19: Alphabet | B19: 9.4 | C19: P/S TTM
A20: Meta | B20: 7 | C20: P/S TTM
A21: Palantir | B21: 61 | C21: EV/Revenue — верх диапазона для лидеров ИИ
A23: 3. МЕТОД 1 — МУЛЬТИПЛИКАТОРЫ ВЫРУЧКИ
A24: Сценарий | B24: Год выхода | C24: Лет до выхода | D24: Выручка на выходе, $ млрд | E24: EV/Revenue, x | F24: Оценка на выходе, $ млрд | G24: MOIC, x | H24: Upside, % | I24: IRR, %
A25: Консервативный | B25: 2027 | C25: 1.5 | D25: 62 | E25: 18 | F25: =D25*E25 -> 1116 | G25: =F25/B12 -> 1.1747616 | H25: =G25-1 -> 0.17476157 | I25: =G25^(1/C25)-1 -> 0.1133537
A26: Базовый | B26: 2028 | C26: 2 | D26: 110 | E26: 15 | F26: =D26*E26 -> 1650 | G26: =F26/B12 -> 1.7368787 | H26: =G26-1 -> 0.73687867 | I26: =G26^(1/C26)-1 -> 0.31790693
A27: Оптимистичный | B27: 2028 | C27: 2 | D27: 110 | E27: 28 | F27: =D27*E27 -> 3080 | G27: =F27/B12 -> 3.2421735 | H27: =G27-1 -> 2.2421735 | I27: =G27^(1/C27)-1 -> 0.80060365
A28: Run-rate выручки >$40 млрд (июль 2026), удвоение за год; план компании ~$62 млрд в 2027 и >$280 млрд к 2030. Целевой сценарий — выручка 2028 ~$110 млрд при мультипликаторе 20x (ниже текущих ~21x ARR).
A30: 4. МЕТОД 2 — РЫНОЧНЫЕ ЯКОРЯ
A31: Сценарий | B31: Год выхода | C31: Лет до выхода | D31: Якорь оценки | E31: Оценка на выходе, $ млрд | F31: MOIC, x | G31: Upside, % | H31: IRR, %
A32: Консервативный | B32: 2027 | C32: 1.5 | D32: IPO по нижней границе: $1 трлн («ниже $1 трлн — nonstarter», С. Альтман) | E32: 1000 | F32: =E32/B12 -> 1.0526537 | G32: =F32-1 -> 0.05265374 | H32: =F32^(1/C32)-1 -> 0.034801442
A33: Базовый | B33: 2028 | C33: 2 | D33: IPO 2026–27 в диапазоне $1.5–1.6 трлн | E33: 1550 | F33: =E33/B12 -> 1.6316133 | G33: =F33-1 -> 0.6316133 | H33: =F33^(1/C33)-1 -> 0.27734619
A34: Оптимистичный | B34: 2028 | C34: 2 | D34: Траектория крупнейшей публичной компании мира | E34: 2200 | F34: =E34/B12 -> 2.3158382 | G34: =F34-1 -> 1.3158382 | H34: =F34^(1/C34)-1 -> 0.52178784
A35: 5. ИТОГ — БАЗОВЫЙ СЦЕНАРИЙ
A36: Оценка на выходе (среднее 2 методов), $ млрд | B36: =AVERAGE(F26,E33) -> 1600
A37: MOIC (базовый) | B37: =B36/B12 -> 1.684246
A38: Upside (базовый) | B38: =B37-1 -> 0.68424598
A39: Доходность инвестора, IRR (базовый) | B39: =B37^(1/C26)-1 -> 0.29778503
A40: Диапазон MOIC (мин. — макс. по всем сценариям) | B40: =MIN(G25,F32) -> 1.0526537 | C40: =MAX(G27,F34) -> 3.2421735
A41: Справочно: MOIC от верхней границы вторичного рынка | B41: =B36/B11 -> 1.6329863
A43: ИСТОЧНИКИ И ПРИМЕЧАНИЯ
A44: • Оценка $852 млрд: CNBC/Bloomberg, 31.03.2026; тендер $7 млрд: CNBC, 10.08.2026
A45: • Выручка: Bloomberg, 13.08.2026 (run-rate >$40 млрд); FY2025 факт $13.07 млрд
...

Sheet Figure AI
A1: Figure AI
A2: Гуманоидные роботы для промышленности
A4: 1. ЦЕНА
A5: Последний закрытый раунд | B5: Series C >$1 млрд, закрыт 16.09.2025; лид Parkway Venture Capital
A6: Оценка по последнему раунду, $ млрд | B6: 39
A7: База для вторичного рынка, $ млрд | B7: 39
A8: Премия к базе — нижняя граница | B8: 0.08
A9: Премия к базе — верхняя граница | B9: 0.15
A10: Цена на вторичном рынке — низ, $ млрд | B10: 30
A11: Цена на вторичном рынке — верх, $ млрд | B11: 33
A12: Цена входа в расчётах (середина диапазона), $ млрд | B12: =AVERAGE(B10:B11) -> 31.5
A13: Примечание | B13: Диапазон — фактические котировки вторичного рынка. Бумага торгуется с дисконтом к Series C: Forge $174.00/акция (13–15.08.2026), Nasdaq Private Market $162.71 (16.06.2026).
A15: 2. ПУБЛИЧНЫЕ АНАЛОГИ
A16: Компания | B16: Мультипликатор, x | C16: Комментарий
A17: Tesla | B17: 15 | C17: EV/Revenue — ИИ/робо-премия
A18: Intuitive Surgical | B18: 15.7 | C18: премиальная робототехника
A19: Fanuc | B19: 7.3 | C19: промышленные роботы
A20: Rockwell Automation | B20: 6.3 | C20: автоматизация
A21: ABB | B21: 2.6 | C21: диверсифицированная автоматизация
A23: 3. МЕТОД 1 — МУЛЬТИПЛИКАТОРЫ ВЫРУЧКИ
A24: Сценарий | B24: Год выхода | C24: Лет до выхода | D24: Выручка на выходе, $ млрд | E24: EV/Revenue, x | F24: Оценка на выходе, $ млрд | G24: MOIC, x | H24: Upside, % | I24: IRR, %
A25: Консервативный | B25: 2029 | C25: 3 | D25: 3.5 | E25: 15 | F25: =D25*E25 -> 52.5 | G25: =F25/B12 -> 1.6666667 | H25: =G25-1 -> 0.66666667 | I25: =G25^(1/C25)-1 -> 0.1856311
A26: Базовый | B26: 2030 | C26: 3.5 | D26: 7 | E26: 15 | F26: =D26*E26 -> 105 | G26: =F26/B12 -> 3.3333333 | H26: =G26-1 -> 2.3333333 | I26: =G26^(1/C26)-1 -> 0.41056768
A27: Оптимистичный | B27: 2030 | C27: 3.5 | D27: 12 | E27: 18 | F27: =D27*E27 -> 216 | G27: =F27/B12 -> 6.8571429 | H27: =G27-1 -> 5.8571429 | I27: =G27^(1/C27)-1 -> 0.73339706
A28: Мощность BotQ до 100 тыс. роботов/год; заказ UPS до ~100 тыс. роботов к 2029. При 60–80 тыс. поставок/год и ASP/RaaS ~$100–130 тыс. выручка выходит на $8–12 млрд.
A30: 4. МЕТОД 2 — РЫНОЧНЫЕ ЯКОРЯ
A31: Сценарий | B31: Год выхода | C31: Лет до выхода | D31: Якорь оценки | E31: Оценка на выходе, $ млрд | F31: MOIC, x | G31: Upside, % | H31: IRR, %
A32: Консервативный | B32: 2029 | C32: 3 | D32: Оценка на уровне Series C ($39 млрд) | E32: 39 | F32: =E32/B12 -> 1.2380952 | G32: =F32-1 -> 0.23809524 | H32: =F32^(1/C32)-1 -> 0.073786693
A33: Базовый | B33: 2030 | C33: 3.5 | D33: IPO лидера категории гуманоидов (нарратив «Tesla робототехники») | E33: 95 | F33: =E33/B12 -> 3.015873 | G33: =F33-1 -> 2.015873 | H33: =F33^(1/C33)-1 -> 0.37080335
A34: Оптимистичный | B34: 2030 | C34: 3.5 | D34: Ре-рейтинг на массовых поставках | E34: 180 | F34: =E34/B12 -> 5.7142857 | G34: =F34-1 -> 4.7142857 | H34: =F34^(1/C34)-1 -> 0.64541269
A35: 5. ИТОГ — БАЗОВЫЙ СЦЕНАРИЙ
A36: Оценка на выходе (среднее 2 методов), $ млрд | B36: =AVERAGE(F26,E33) -> 100
A37: MOIC (базовый) | B37: =B36/B12 -> 3.1746032
A38: Upside (базовый) | B38: =B37-1 -> 2.1746032
A39: Доходность инвестора, IRR (базовый) | B39: =B37^(1/C26)-1 -> 0.39104072
A40: Диапазон MOIC (мин. — макс. по всем сценариям) | B40: =MIN(G25,F32) -> 1.2380952 | C40: =MAX(G27,F34) -> 6.8571429
A41: Справочно: MOIC от верхней границы вторичного рынка | B41: =B36/B11 -> 3.030303
A43: ИСТОЧНИКИ И ПРИМЕЧАНИЯ
A44: • Series C $39 млрд: figure.ai/news/series-c; TechCrunch, 16.09.2025
A45: • BMW Spartanburg (Figure 03 в продакшне с июня 2026), UPS — по сообщениям СМИ
...

Sheet 1X
A1: 1X Technologies
A2: Домашние роботы-помощники
A4: 1. ЦЕНА
A5: Последний закрытый раунд | B5: Series C, до $1 млрд, в процессе — оценка $10+ млрд (предыдущий закрытый: Series B $100 млн, январь 2024, лид EQT Ventures)
A6: Оценка по последнему раунду, $ млрд | B6: 10
A7: База для вторичного рынка, $ млрд | B7: 10
A8: Премия к базе — нижняя граница | B8: 0.08
A9: Премия к базе — верхняя граница | B9: 0.15
A10: Цена на вторичном рынке — низ, $ млрд | B10: 10.5
A11: Цена на вторичном рынке — верх, $ млрд | B11: 12
A12: Цена входа в расчётах (середина диапазона), $ млрд | B12: =AVERAGE(B10:B11) -> 11.25
A13: Примечание | B13: Диапазон — фактические котировки вторичного рынка. Оценка идущего Series C — $10+ млрд (The Information); Nasdaq Private Market ~$662/акция (31.07.2026). Закрытый Series B (01.2024, $0.82 млрд) устарел и в расчёте не используется.
A15: 2. ПУБЛИЧНЫЕ АНАЛОГИ
A16: Компания | B16: Мультипликатор, x | C16: Комментарий
A17: Tesla | B17: 15 | C17: EV/Revenue — ИИ/робо-премия
A18: Intuitive Surgical | B18: 15.7 | C18: премиальная робототехника
A19: iRobot | B19: 1 | C19: предостерегающий комп: консьюмер-железо без ИИ-рва
A23: 3. МЕТОД 1 — МУЛЬТИПЛИКАТОРЫ ВЫРУЧКИ
A24: Сценарий | B24: Год выхода | C24: Лет до выхода | D24: Выручка на выходе, $ млрд | E24: EV/Revenue, x | F24: Оценка на выходе, $ млрд | G24: MOIC, x | H24: Upside, % | I24: IRR, %
A25: Консервативный | B25: 2029 | C25: 2.5 | D25: 2 | E25: 12 | F25: =D25*E25 -> 24 | G25: =F25/B12 -> 2.1333333 | H25: =G25-1 -> 1.1333333 | I25: =G25^(1/C25)-1 -> 0.35401504
A26: Базовый | B26: 2029 | C26: 2.5 | D26: 3.5 | E26: 12 | F26: =D26*E26 -> 42 | G26: =F26/B12 -> 3.7333333 | H26: =G26-1 -> 2.7333333 | I26: =G26^(1/C26)-1 -> 0.69370866
A27: Оптимистичный | B27: 2030 | C27: 3.5 | D27: 7 | E27: 15 | F27: =D27*E27 -> 105 | G27: =F27/B12 -> 9.3333333 | H27: =G27-1 -> 8.3333333 | I27: =G27^(1/C27)-1 -> 0.89301199
A28: Цель — 100 тыс. роботов/год к концу 2027. Парк 150–250 тыс. штук к 2029 при $20 тыс. за робота или $6 тыс./год подписки даёт выручку $3–4 млрд (базовый сценарий — $3.5 млрд).
A30: 4. МЕТОД 2 — РЫНОЧНЫЕ ЯКОРЯ
A31: Сценарий | B31: Год выхода | C31: Лет до выхода | D31: Якорь оценки | E31: Оценка на выходе, $ млрд | F31: MOIC, x | G31: Upside, % | H31: IRR, %
A32: Консервативный | B32: 2029 | C32: 2.5 | D32: Оценка на уровне идущего Series C ($10 млрд) | E32: 10 | F32: =E32/B12 -> 0.88888889 | G32: =F32-1 -> -0.11111111 | H32: =F32^(1/C32)-1 -> -0.046020613
A33: Базовый | B33: 2029 | C33: 2.5 | D33: Кратный рост к идущему Series C при выходе NEO на серийные поставки | E33: 38 | F33: =E33/B12 -> 3.3777778 | G33: =F33-1 -> 2.3777778 | H33: =F33^(1/C33)-1 -> 0.62724307
A34: Оптимистичный | B34: 2030 | C34: 3.5 | D34: Массовое проникновение домашних роботов | E34: 90 | F34: =E34/B12 -> 8 | G34: =F34-1 -> 7 | H34: =F34^(1/C34)-1 -> 0.81144733
A35: 5. ИТОГ — БАЗОВЫЙ СЦЕНАРИЙ
A36: Оценка на выходе (среднее 2 методов), $ млрд | B36: =AVERAGE(F26,E33) -> 40
A37: MOIC (базовый) | B37: =B36/B12 -> 3.5555556
A38: Upside (базовый) | B38: =B37-1 -> 2.5555556
A39: Доходность инвестора, IRR (базовый) | B39: =B37^(1/C26)-1 -> 0.66097459
A40: Диапазон MOIC (мин. — макс. по всем сценариям) | B40: =MIN(G25,F32) -> 0.88888889 | C40: =MAX(G27,F34) -> 9.3333333
A41: Справочно: MOIC от верхней границы вторичного рынка | B41: =B36/B11 -> 3.3333333
A43: ИСТОЧНИКИ И ПРИМЕЧАНИЯ
A44: • Series B $100 млн: 1x.tech, январь 2024; Series C в процессе: The Information, сентябрь 2025
A45: • NEO: 10 тыс.+ предзаказов за 5 дней (бэклог >$200 млн); производство в Hayward, CA с апреля 2026
A46: • EQT: контракт до 10 тыс. роботов для портфельных компаний 2026–2030
A47: • Цена на вторичном рынке индикативна; реальная цена — по запросу на момент сделки.

Sheet Polymarket
A1: Polymarket
A2: Рынки предсказаний
A4: 1. ЦЕНА
A5: Последний закрытый раунд | B5: Раунд ~$1 млрд, закрыт в апреле 2026; новые инвесторы D.E. Shaw и G Squared, ICE добавила $600 млн
A6: Оценка по последнему раунду, $ млрд | B6: 15
A7: База для вторичного рынка, $ млрд | B7: 15
A8: Премия к базе — нижняя граница | B8: 0.08
A9: Премия к базе — верхняя граница | B9: 0.15
A10: Цена на вторичном рынке — низ, $ млрд | B10: 13.5
A11: Цена на вторичном рынке — верх, $ млрд | B11: 15
A12: Цена входа в расчётах (середина диапазона), $ млрд | B12: =AVERAGE(B10:B11) -> 14.25
A13: Примечание | B13: Диапазон — фактические котировки вторичного рынка. Вторичные сделки идут вблизи апрельской отметки раунда; для справки: Bloomberg/CNBC (04.08.2026) сообщали о переговорах по раунду выше $20 млрд.
A15: 2. ПУБЛИЧНЫЕ АНАЛОГИ
A16: Компания | B16: Мультипликатор, x | C16: Комментарий
A17: Robinhood | B17: 20.7 | C17: EV/Revenue
A18: CME Group | B18: 17 | C18: биржевой оператор
A19: ICE | B19: 9 | C19: 8–10x, стратегический акционер
A20: Coinbase | B20: 5.9 | C20: крипто-биржа
A21: DraftKings | B21: 2.1 | C21: беттинг — нижняя граница
A23: 3. МЕТОД 1 — МУЛЬТИПЛИКАТОРЫ ВЫРУЧКИ
A24: Сценарий | B24: Год выхода | C24: Лет до выхода | D24: Выручка на выходе, $ млрд | E24: EV/Revenue, x | F24: Оценка на выходе, $ млрд | G24: MOIC, x | H24: Upside, % | I24: IRR, %
A25: Консервативный | B25: 2028 | C25: 2 | D25: 2.5 | E25: 15 | F25: =D25*E25 -> 37.5 | G25: =F25/B12 -> 2.6315789 | H25: =G25-1 -> 1.6315789 | I25: =G25^(1/C25)-1 -> 0.62221421
A26: Базовый | B26: 2029 | C26: 2.5 | D26: 3 | E26: 15 | F26: =D26*E26 -> 45 | G26: =F26/B12 -> 3.1578947 | H26: =G26-1 -> 2.1578947 | I26: =G26^(1/C26)-1 -> 0.58401416
A27: Оптимистичный | B27: 2030 | C27: 3.5 | D27: 6 | E27: 18 | F27: =D27*E27 -> 108 | G27: =F27/B12 -> 7.5789474 | H27: =G27-1 -> 6.5789474 | I27: =G27^(1/C27)-1 -> 0.78367952
A28: Annualized-выручка >$1 млрд уже через 6 недель после запуска биржи в США. Bernstein: объёмы отрасли $1 трлн к 2030; при доле ~30% и комиссии ~2% выручка Polymarket выходит на $6 млрд.
A30: 4. МЕТОД 2 — РЫНОЧНЫЕ ЯКОРЯ
A31: Сценарий | B31: Год выхода | C31: Лет до выхода | D31: Якорь оценки | E31: Оценка на выходе, $ млрд | F31: MOIC, x | G31: Upside, % | H31: IRR, %
A32: Консервативный | B32: 2028 | C32: 2 | D32: Оценка идущего раунда (>$20 млрд) | E32: 22 | F32: =E32/B12 -> 1.5438596 | G32: =F32-1 -> 0.54385965 | H32: =F32^(1/C32)-1 -> 0.24252149
A33: Базовый | B33: 2029 | C33: 2.5 | D33: Паритет с Kalshi по обороту + премия за глобальный рынок | E33: 45 | F33: =E33/B12 -> 3.1578947 | G33: =F33-1 -> 2.1578947 | H33: =F33^(1/C33)-1 -> 0.58401416
A34: Оптимистичный | B34: 2030 | C34: 3.5 | D34: Ре-рейтинг категории до биржевой инфраструктуры (CME/ICE) | E34: 100 | F34: =E34/B12 -> 7.0175439 | G34: =F34-1 -> 6.0175439 | H34: =F34^(1/C34)-1 -> 0.7448865
A35: 5. ИТОГ — БАЗОВЫЙ СЦЕНАРИЙ
A36: Оценка на выходе (среднее 2 методов), $ млрд | B36: =AVERAGE(F26,E33) -> 45
A37: MOIC (базовый) | B37: =B36/B12 -> 3.1578947
A38: Upside (базовый) | B38: =B37-1 -> 2.1578947
A39: Доходность инвестора, IRR (базовый) | B39: =B37^(1/C26)-1 -> 0.58401416
A40: Диапазон MOIC (мин. — макс. по всем сценариям) | B40: =MIN(G25,F32) -> 1.5438596 | C40: =MAX(G27,F34) -> 7.5789474
A41: Справочно: MOIC от верхней границы вторичного рынка | B41: =B36/B11 -> 3
A43: ИСТОЧНИКИ И ПРИМЕЧАНИЯ
A44: • Раунд $15 млрд: Bloomberg 20.04.2026; раунд >$20 млрд в переговорах: Bloomberg/CNBC 04.08.2026
A45: • Выручка >$1 млрд annualized: CNBC, 26.06.2026; обороты ~$9–10.5 млрд/мес
...

Sheet Kalshi
A1: Kalshi
A2: Рынки предсказаний (США)
A4: 1. ЦЕНА
A5: Последний закрытый раунд | B5: Series F $1 млрд, закрыт 07.05.2026; лид Coatue (Sequoia, a16z, IVP, Paradigm, Morgan Stanley, ARK)
A6: Оценка по последнему раунду, $ млрд | B6: 22
A7: База для вторичного рынка, $ млрд | B7: 22
A8: Премия к базе — нижняя граница | B8: 0.08
A9: Премия к базе — верхняя граница | B9: 0.15
A10: Цена на вторичном рынке — низ, $ млрд | B10: 30
A11: Цена на вторичном рынке — верх, $ млрд | B11: 40
A12: Цена входа в расчётах (середина диапазона), $ млрд | B12: =AVERAGE(B10:B11) -> 35
A13: Примечание | B13: Диапазон — фактические котировки вторичного рынка. Фактические сделки на вторичном рынке идут около $35 млрд: рынок уже отыгрывает раунд по оценке $40 млрд, который обсуждают Sequoia и Wellington (CoinDesk, 13.08.2026).
A15: 2. ПУБЛИЧНЫЕ АНАЛОГИ
A16: Компания | B16: Мультипликатор, x | C16: Комментарий
A17: Robinhood | B17: 20 | C17: EV/Revenue
A18: CME Group | B18: 13 | C18: биржевой оператор
A19: Coinbase | B19: 7 | C19: биржа
A20: DraftKings | B20: 2 | C20: беттинг — нижняя граница
A23: 3. МЕТОД 1 — МУЛЬТИПЛИКАТОРЫ ВЫРУЧКИ
A24: Сценарий | B24: Год выхода | C24: Лет до выхода | D24: Выручка на выходе, $ млрд | E24: EV/Revenue, x | F24: Оценка на выходе, $ млрд | G24: MOIC, x | H24: Upside, % | I24: IRR, %
A25: Консервативный | B25: 2028 | C25: 2 | D25: 4 | E25: 10 | F25: =D25*E25 -> 40 | G25: =F25/B12 -> 1.1428571 | H25: =G25-1 -> 0.14285714 | I25: =G25^(1/C25)-1 -> 0.069044968
A26: Базовый | B26: 2028 | C26: 2 | D26: 6 | E26: 12 | F26: =D26*E26 -> 72 | G26: =F26/B12 -> 2.0571429 | H26: =G26-1 -> 1.0571429 | I26: =G26^(1/C26)-1 -> 0.43427433
A27: Оптимистичный | B27: 2029 | C27: 3 | D27: 10 | E27: 15 | F27: =D27*E27 -> 150 | G27: =F27/B12 -> 4.2857143 | H27: =G27-1 -> 3.2857143 | I27: =G27^(1/C27)-1 -> 0.62433052
A28: Выручка: $263.5 млн за 2025 → run-rate ~$4 млрд к июлю 2026 (пик ЧМ по футболу). Базовый сценарий консервативен: $6 млрд выручки к 2028 при мультипликаторе биржевых операторов 12x.
A30: 4. МЕТОД 2 — РЫНОЧНЫЕ ЯКОРЯ
A31: Сценарий | B31: Год выхода | C31: Лет до выхода | D31: Якорь оценки | E31: Оценка на выходе, $ млрд | F31: MOIC, x | G31: Upside, % | H31: IRR, %
A32: Консервативный | B32: 2028 | C32: 2 | D32: Оценка идущего раунда ($40 млрд) | E32: 40 | F32: =E32/B12 -> 1.1428571 | G32: =F32-1 -> 0.14285714 | H32: =F32^(1/C32)-1 -> 0.069044968
A33: Базовый | B33: 2028 | C33: 2 | D33: IPO ~2027–28 при мультипликаторах биржевых операторов | E33: 78 | F33: =E33/B12 -> 2.2285714 | G33: =F33-1 -> 1.2285714 | H33: =F33^(1/C33)-1 -> 0.49284005
A34: Оптимистичный | B34: 2029 | C34: 3 | D34: Категория выходит на объёмы $1.5 трлн (Macquarie) | E34: 150 | F34: =E34/B12 -> 4.2857143 | G34: =F34-1 -> 3.2857143 | H34: =F34^(1/C34)-1 -> 0.62433052
A35: 5. ИТОГ — БАЗОВЫЙ СЦЕНАРИЙ
A36: Оценка на выходе (среднее 2 методов), $ млрд | B36: =AVERAGE(F26,E33) -> 75
A37: MOIC (базовый) | B37: =B36/B12 -> 2.1428571
A38: Upside (базовый) | B38: =B37-1 -> 1.1428571
A39: Доходность инвестора, IRR (базовый) | B39: =B37^(1/C26)-1 -> 0.46385011
A40: Диапазон MOIC (мин. — макс. по всем сценариям) | B40: =MIN(G25,F32) -> 1.1428571 | C40: =MAX(G27,F34) -> 4.2857143
A41: Справочно: MOIC от верхней границы вторичного рынка | B41: =B36/B11 -> 1.875
A43: ИСТОЧНИКИ И ПРИМЕЧАНИЯ
A44: • Series F $1 млрд @ $22 млрд: TechCrunch/BusinessWire, 07.05.2026
A45: • Раунд @ $40 млрд в переговорах: CoinDesk, 13.08.2026
A46: • Выручка 2025 $263.5 млн, run-rate ~$4 млрд (июль 2026); всего привлечено ~$2.8 млрд
...

Sheet Positron AI
A1: Positron AI
A2: Чипы для ИИ (инференс)
A4: 1. ЦЕНА
A5: Последний закрытый раунд | B5: Series B $230 млн (переподписан), закрыт 04.02.2026; со-лиды ARENA, Jump Trading, Unless; стратеги QIA и Arm
A6: Оценка по последнему раунду, $ млрд | B6: 1
A7: База для вторичного рынка, $ млрд (оценка идущего раунда) | B7: 3.5
A8: Премия к базе — нижняя граница | B8: 0.08
A9: Премия к базе — верхняя граница | B9: 0.15
A10: Цена на вторичном рынке — низ, $ млрд | B10: 4.5
A11: Цена на вторичном рынке — верх, $ млрд | B11: 5
A12: Цена входа в расчётах (середина диапазона), $ млрд | B12: =AVERAGE(B10:B11) -> 4.75
A13: Примечание | B13: Диапазон — фактические котировки вторичного рынка. Bloomberg (08.07.2026): раунд ~$750 млн двумя траншами по оценкам ~$3.5 и ~$5 млрд — вторичный рынок торгуется по верхней границе этих переговоров, кратно выше Series B.
A15: 2. ПУБЛИЧНЫЕ АНАЛОГИ
A16: Компания | B16: Мультипликатор, x | C16: Комментарий
A17: NVIDIA | B17: 20.6 | C17: EV/Revenue
A18: Broadcom | B18: 24.5 | C18: EV/Revenue
A19: AMD | B19: 18 | C19: EV/Revenue
A20: Marvell | B20: 16.9 | C20: EV/Revenue
A23: 3. МЕТОД 1 — МУЛЬТИПЛИКАТОРЫ ВЫРУЧКИ
A24: Сценарий | B24: Год выхода | C24: Лет до выхода | D24: Выручка на выходе, $ млрд | E24: EV/Revenue, x | F24: Оценка на выходе, $ млрд | G24: MOIC, x | H24: Upside, % | I24: IRR, %
A25: Консервативный | B25: 2029 | C25: 3 | D25: 0.6 | E25: 15 | F25: =D25*E25 -> 9 | G25: =F25/B12 -> 1.8947368 | H25: =G25-1 -> 0.89473684 | I25: =G25^(1/C25)-1 -> 0.23741763
A26: Базовый | B26: 2030 | C26: 3.5 | D26: 1.4 | E26: 17 | F26: =D26*E26 -> 23.8 | G26: =F26/B12 -> 5.0105263 | H26: =G26-1 -> 4.0105263 | I26: =G26^(1/C26)-1 -> 0.58477157
A27: Оптимистичный | B27: 2031 | C27: 4.5 | D27: 2 | E27: 18 | F27: =D27*E27 -> 36 | G27: =F27/B12 -> 7.5789474 | H27: =G27-1 -> 6.5789474 | I27: =G27^(1/C27)-1 -> 0.56844265
A28: Букинги: контракт Oracle $50.4 млн (344 сервера Atlas), Cloudflare, Parasail. Целевой сценарий — ramp собственного чипа Asimov (производство с 2027) до выручки ~$1.8 млрд к 2029; рынок инференс-чипов $37 млрд к 2030.
A30: 4. МЕТОД 2 — РЫНОЧНЫЕ ЯКОРЯ
A31: Сценарий | B31: Год выхода | C31: Лет до выхода | D31: Якорь оценки | E31: Оценка на выходе, $ млрд | F31: MOIC, x | G31: Upside, % | H31: IRR, %
A32: Консервативный | B32: 2029 | C32: 3 | D32: Оценка верхнего транша идущего раунда ($5 млрд) | E32: 5 | F32: =E32/B12 -> 1.0526316 | G32: =F32-1 -> 0.052631579 | H32: =F32^(1/C32)-1 -> 0.017244768
A33: Базовый | B33: 2030 | C33: 3.5 | D33: Путь Cerebras: IPO при выручке $1 млрд+ или продажа стратегу (Arm в капитале) | E33: 24.2 | F33: =E33/B12 -> 5.0947368 | G33: =F33-1 -> 4.0947368 | H33: =F33^(1/C33)-1 -> 0.59233627
A34: Оптимистичный | B34: 2031 | C34: 4.5 | D34: Закрепление доли в инференсе против Nvidia | E34: 40 | F34: =E34/B12 -> 8.4210526 | G34: =F34-1 -> 7.4210526 | H34: =F34^(1/C34)-1 -> 0.60559857
A35: 5. ИТОГ — БАЗОВЫЙ СЦЕНАРИЙ
A36: Оценка на выходе (среднее 2 методов), $ млрд | B36: =AVERAGE(F26,E33) -> 24
A37: MOIC (базовый) | B37: =B36/B12 -> 5.0526316
A38: Upside (базовый) | B38: =B37-1 -> 4.0526316
A39: Доходность инвестора, IRR (базовый) | B39: =B37^(1/C26)-1 -> 0.58856518
A40: Диапазон MOIC (мин. — макс. по всем сценариям) | B40: =MIN(G25,F32) -> 1.0526316 | C40: =MAX(G27,F34) -> 8.4210526
A41: Справочно: MOIC от верхней границы вторичного рынка | B41: =B36/B11 -> 4.8
A43: ИСТОЧНИКИ И ПРИМЕЧАНИЯ
A44: • Series B $230 млн, >$1 млрд post: BusinessWire/TechCrunch, 04.02.2026
A45: • Раунд по $3.5–5 млрд в переговорах: Bloomberg, 08.07.2026
A46: • Контракт Oracle: EE Times, апрель 2026; TAM инференс-чипов $37 млрд к 2030
...

Sheet Databricks
A1: Databricks
A2: Данные и ИИ для корпораций
A4: 1. ЦЕНА
A5: Последний закрытый раунд | B5: Стратегический раунд $5 млрд, закрыт 13.08.2026; лид Coatue (спрос ~$15 млрд)
A6: Оценка по последнему раунду, $ млрд | B6: 190
A7: База для вторичного рынка, $ млрд | B7: 190
A8: Премия к базе — нижняя граница | B8: 0.08
A9: Премия к базе — верхняя граница | B9: 0.15
A10: Цена на вторичном рынке — низ, $ млрд | B10: 195
A11: Цена на вторичном рынке — верх, $ млрд | B11: 210
A12: Цена входа в расчётах (середина диапазона), $ млрд | B12: =AVERAGE(B10:B11) -> 202.5
A13: Примечание | B13: Диапазон — фактические котировки вторичного рынка. Раунд закрыт в августе 2026 при переподписке втрое; вторичные сделки перед IPO идут с премией к раунду.
A15: 2. ПУБЛИЧНЫЕ АНАЛОГИ
A16: Компания | B16: Мультипликатор, x | C16: Комментарий
A17: Snowflake | B17: 21 | C17: EV/Revenue — прямой аналог
A18: Palantir | B18: 61 | C18: верх диапазона
A19: MongoDB | B19: 10 | C19: инфраструктура данных
A20: Microsoft | B20: 10.5 | C20: мегакэп
A23: 3. МЕТОД 1 — МУЛЬТИПЛИКАТОРЫ ВЫРУЧКИ
A24: Сценарий | B24: Год выхода | C24: Лет до выхода | D24: Выручка на выходе, $ млрд | E24: EV/Revenue, x | F24: Оценка на выходе, $ млрд | G24: MOIC, x | H24: Upside, % | I24: IRR, %
A25: Консервативный | B25: 2028 | C25: 2 | D25: 14 | E25: 18 | F25: =D25*E25 -> 252 | G25: =F25/B12 -> 1.2444444 | H25: =G25-1 -> 0.24444444 | I25: =G25^(1/C25)-1 -> 0.1155467
A26: Базовый | B26: 2028 | C26: 2 | D26: 16 | E26: 26.5 | F26: =D26*E26 -> 424 | G26: =F26/B12 -> 2.0938272 | H26: =G26-1 -> 1.0938272 | I26: =G26^(1/C26)-1 -> 0.44700628
A27: Оптимистичный | B27: 2029 | C27: 3 | D27: 25 | E27: 25 | F27: =D27*E27 -> 625 | G27: =F27/B12 -> 3.0864198 | H27: =G27-1 -> 2.0864198 | I27: =G27^(1/C27)-1 -> 0.45596744
A28: Run-rate $7 млрд (июль 2026) при росте >80% г/г с ускорением и положительном денежном потоке. Сохранение темпа даёт ~$16 млрд к 2028; Snowflake торгуется по 21x, Palantir — по 61x.
A30: 4. МЕТОД 2 — РЫНОЧНЫЕ ЯКОРЯ
A31: Сценарий | B31: Год выхода | C31: Лет до выхода | D31: Якорь оценки | E31: Оценка на выходе, $ млрд | F31: MOIC, x | G31: Upside, % | H31: IRR, %
A32: Консервативный | B32: 2028 | C32: 2 | D32: Оценка остаётся на уровне раунда ($190 млрд) | E32: 190 | F32: =E32/B12 -> 0.9382716 | G32: =F32-1 -> -0.061728395 | H32: =F32^(1/C32)-1 -> -0.03135579
A33: Базовый | B33: 2028 | C33: 2 | D33: IPO 2027–28 — один из крупнейших листингов десятилетия | E33: 426 | F33: =E33/B12 -> 2.1037037 | G33: =F33-1 -> 1.1037037 | H33: =F33^(1/C33)-1 -> 0.45041501
A34: Оптимистичный | B34: 2029 | C34: 3 | D34: Пост-IPO ре-рейтинг на траектории роста >60% | E34: 600 | F34: =E34/B12 -> 2.962963 | G34: =F34-1 -> 1.962963 | H34: =F34^(1/C34)-1 -> 0.43628979
A35: 5. ИТОГ — БАЗОВЫЙ СЦЕНАРИЙ
A36: Оценка на выходе (среднее 2 методов), $ млрд | B36: =AVERAGE(F26,E33) -> 425
A37: MOIC (базовый) | B37: =B36/B12 -> 2.0987654
A38: Upside (базовый) | B38: =B37-1 -> 1.0987654
A39: Доходность инвестора, IRR (базовый) | B39: =B37^(1/C26)-1 -> 0.44871165
A40: Диапазон MOIC (мин. — макс. по всем сценариям) | B40: =MIN(G25,F32) -> 0.9382716 | C40: =MAX(G27,F34) -> 3.0864198
A41: Справочно: MOIC от верхней границы вторичного рынка | B41: =B36/B11 -> 2.0238095
A43: ИСТОЧНИКИ И ПРИМЕЧАНИЯ
A44: • Раунд $5 млрд @ $190 млрд: CNBC, 13.08.2026; пресс-релиз Databricks
A45: • Run-rate $7 млрд, рост >80% г/г: данные компании, квартал до июля 2026
A46: • Всего привлечено ~$25 млрд; IPO: CEO исключил 2026 год
...

Sheet VAST Data
A1: VAST Data
A2: Инфраструктура данных для ИИ
A4: 1. ЦЕНА
A5: Последний закрытый раунд | B5: Series F ~$1 млрд ($500 млн первичных + $500 млн выкуп акций), закрыт 22.04.2026; лид Drive Capital, со-лид Access Industries
A6: Оценка по последнему раунду, $ млрд | B6: 30
A7: База для вторичного рынка, $ млрд | B7: 30
A8: Премия к базе — нижняя граница | B8: 0.08
A9: Премия к базе — верхняя граница | B9: 0.15
A10: Цена на вторичном рынке — низ, $ млрд | B10: 23
A11: Цена на вторичном рынке — верх, $ млрд | B11: 28
A12: Цена входа в расчётах (середина диапазона), $ млрд | B12: =AVERAGE(B10:B11) -> 25.5
A13: Примечание | B13: Диапазон — фактические котировки вторичного рынка. Бумага торгуется с дисконтом к апрельскому раунду ($30 млрд): половина сделки Series F пришлась на выкуп акций, что уже удовлетворило часть спроса на выход.
A15: 2. ПУБЛИЧНЫЕ АНАЛОГИ
A16: Компания | B16: Мультипликатор, x | C16: Комментарий
A17: Snowflake | B17: 21 | C17: EV/Revenue — ближайший аналог по профилю роста
A18: Pure Storage | B18: 6.1 | C18: хранение данных
A19: Nutanix | B19: 4.7 | C19: инфраструктурный софт
A20: NetApp | B20: 3.2 | C20: традиционное хранение — нижняя граница
A23: 3. МЕТОД 1 — МУЛЬТИПЛИКАТОРЫ ВЫРУЧКИ
A24: Сценарий | B24: Год выхода | C24: Лет до выхода | D24: Выручка на выходе, $ млрд | E24: EV/Revenue, x | F24: Оценка на выходе, $ млрд | G24: MOIC, x | H24: Upside, % | I24: IRR, %
A25: Консервативный | B25: 2028 | C25: 2 | D25: 1.5 | E25: 20 | F25: =D25*E25 -> 30 | G25: =F25/B12 -> 1.1764706 | H25: =G25-1 -> 0.17647059 | I25: =G25^(1/C25)-1 -> 0.084652289
A26: Базовый | B26: 2029 | C26: 2.5 | D26: 2.5 | E26: 24 | F26: =D26*E26 -> 60 | G26: =F26/B12 -> 2.3529412 | H26: =G26-1 -> 1.3529412 | I26: =G26^(1/C26)-1 -> 0.40813544
A27: Оптимистичный | B27: 2030 | C27: 3.5 | D27: 4 | E27: 28 | F27: =D27*E27 -> 112 | G27: =F27/B12 -> 4.3921569 | H27: =G27-1 -> 3.3921569 | I27: =G27^(1/C27)-1 -> 0.52623792
A28: CARR превысил $500 млн на конец FY2026, цель компании — более $1 млрд к концу FY2027 при валовой марже ~90% и положительном денежном потоке пятый год подряд. Контракт с CoreWeave на $1.17 млрд превышает весь текущий CARR.
A30: 4. МЕТОД 2 — РЫНОЧНЫЕ ЯКОРЯ
A31: Сценарий | B31: Год выхода | C31: Лет до выхода | D31: Якорь оценки | E31: Оценка на выходе, $ млрд | F31: MOIC, x | G31: Upside, % | H31: IRR, %
A32: Консервативный | B32: 2028 | C32: 2 | D32: Оценка остаётся на уровне Series F ($30 млрд) | E32: 30 | F32: =E32/B12 -> 1.1764706 | G32: =F32-1 -> 0.17647059 | H32: =F32^(1/C32)-1 -> 0.084652289
A33: Базовый | B33: 2029 | C33: 2.5 | D33: IPO 2028 с удвоением к оценке раунда | E33: 60 | F33: =E33/B12 -> 2.3529412 | G33: =F33-1 -> 1.3529412 | H33: =F33^(1/C33)-1 -> 0.40813544
A34: Оптимистичный | B34: 2030 | C34: 3.5 | D34: Ре-рейтинг как инфраструктуры ИИ первого эшелона | E34: 100 | F34: =E34/B12 -> 3.9215686 | G34: =F34-1 -> 2.9215686 | H34: =F34^(1/C34)-1 -> 0.47761043
A35: 5. ИТОГ — БАЗОВЫЙ СЦЕНАРИЙ
A36: Оценка на выходе (среднее 2 методов), $ млрд | B36: =AVERAGE(F26,E33) -> 60
A37: MOIC (базовый) | B37: =B36/B12 -> 2.3529412
A38: Upside (базовый) | B38: =B37-1 -> 1.3529412
A39: Доходность инвестора, IRR (базовый) | B39: =B37^(1/C26)-1 -> 0.40813544
A40: Диапазон MOIC (мин. — макс. по всем сценариям) | B40: =MIN(G25,F32) -> 1.1764706 | C40: =MAX(G27,F34) -> 4.3921569
A41: Справочно: MOIC от верхней границы вторичного рынка | B41: =B36/B11 -> 2.1428571
A43: ИСТОЧНИКИ И ПРИМЕЧАНИЯ
A44: • Series F $30 млрд post-money: анонс 22.04.2026; лид Drive Capital, со-лид Access Industries
A45: • CARR >$500 млн (FY2026), цель >$1 млрд (FY2027), маржа ~90%: данные компании
A46: • IPO: CEO Ренен Халлак — готовность к листингу к концу 2026 (Axios Pro, 22.04.2026); S-1 не подана
...

Sheet ByteDance
A1: ByteDance
A2: Соцсети и цифровая реклама
A4: 1. ЦЕНА
A5: Последний закрытый раунд | B5: Выкуп акций у сотрудников по $229.50 за акцию, 15.04.2026 (+14.5% к октябрю 2025) — имплайд-оценка $400–450 млрд
A6: Оценка по последнему раунду, $ млрд | B6: 425
A7: База для вторичного рынка, $ млрд | B7: 425
A8: Премия к базе — нижняя граница | B8: 0.08
A9: Премия к базе — верхняя граница | B9: 0.15
A10: Цена на вторичном рынке — низ, $ млрд | B10: 590
A11: Цена на вторичном рынке — верх, $ млрд | B11: 610
A12: Цена входа в расчётах (середина диапазона), $ млрд | B12: =AVERAGE(B10:B11) -> 600
A13: Примечание | B13: Диапазон — фактические котировки вторичного рынка. Reuters (февраль 2026): General Atlantic продавал пакет по оценке $550 млрд; к апрелю 2026 биды поднялись выше $600 млрд. Официальный выкуп для сотрудников идёт по более низкой оценке.
A15: 2. ПУБЛИЧНЫЕ АНАЛОГИ
A16: Компания | B16: Мультипликатор, x | C16: Комментарий
A17: Meta | B17: 7.5 | C17: EV/Revenue — прямой аналог по рекламе
A18: Reddit | B18: 10.7 | C18: соцсети — верх диапазона
A19: Tencent | B19: 4.5 | C19: китайский технологический холдинг
A20: Kuaishou | B20: 2 | C20: прямой конкурент в Китае — нижняя граница
A23: 3. МЕТОД 1 — МУЛЬТИПЛИКАТОРЫ ВЫРУЧКИ
A24: Сценарий | B24: Год выхода | C24: Лет до выхода | D24: Выручка на выходе, $ млрд | E24: EV/Revenue, x | F24: Оценка на выходе, $ млрд | G24: MOIC, x | H24: Upside, % | I24: IRR, %
A25: Консервативный | B25: 2028 | C25: 2 | D25: 220 | E25: 3 | F25: =D25*E25 -> 660 | G25: =F25/B12 -> 1.1 | H25: =G25-1 -> 0.1 | I25: =G25^(1/C25)-1 -> 0.048808848
A26: Базовый | B26: 2028 | C26: 2 | D26: 250 | E26: 3.4 | F26: =D26*E26 -> 850 | G26: =F26/B12 -> 1.4166667 | H26: =G26-1 -> 0.41666667 | I26: =G26^(1/C26)-1 -> 0.19023807
A27: Оптимистичный | B27: 2029 | C27: 3 | D27: 300 | E27: 4.2 | F27: =D27*E27 -> 1260 | G27: =F27/B12 -> 2.1 | H27: =G27-1 -> 1.1 | I27: =G27^(1/C27)-1 -> 0.28057916
A28: Выручка 2025 — около $186 млрд (+20% г/г), фактически вровень с Meta; зарубежная выручка выросла примерно в полтора раза. При сохранении темпа выручка 2027 выходит на $250 млрд; текущая вторичка соответствует ~3.2x EV/Revenue против 7.5x у Meta.
A30: 4. МЕТОД 2 — РЫНОЧНЫЕ ЯКОРЯ
A31: Сценарий | B31: Год выхода | C31: Лет до выхода | D31: Якорь оценки | E31: Оценка на выходе, $ млрд | F31: MOIC, x | G31: Upside, % | H31: IRR, %
A32: Консервативный | B32: 2028 | C32: 2 | D32: Оценка остаётся на уровне текущей вторички ($600 млрд) | E32: 600 | F32: =E32/B12 -> 1 | G32: =F32-1 -> 0 | H32: =F32^(1/C32)-1 -> 0
A33: Базовый | B33: 2028 | C33: 2 | D33: Следующие раунды выкупа и блок-трейды при росте выручки | E33: 850 | F33: =E33/B12 -> 1.4166667 | G33: =F33-1 -> 0.41666667 | H33: =F33^(1/C33)-1 -> 0.19023807
A34: Оптимистичный | B34: 2029 | C34: 3 | D34: Сокращение разрыва в мультипликаторах с Meta | E34: 1200 | F34: =E34/B12 -> 2 | G34: =F34-1 -> 1 | H34: =F34^(1/C34)-1 -> 0.25992105
A35: 5. ИТОГ — БАЗОВЫЙ СЦЕНАРИЙ
A36: Оценка на выходе (среднее 2 методов), $ млрд | B36: =AVERAGE(F26,E33) -> 850
A37: MOIC (базовый) | B37: =B36/B12 -> 1.4166667
A38: Upside (базовый) | B38: =B37-1 -> 0.41666667
A39: Доходность инвестора, IRR (базовый) | B39: =B37^(1/C26)-1 -> 0.19023807
A40: Диапазон MOIC (мин. — макс. по всем сценариям) | B40: =MIN(G25,F32) -> 1 | C40: =MAX(G27,F34) -> 2.1
A41: Справочно: MOIC от верхней границы вторичного рынка | B41: =B36/B11 -> 1.3934426
A43: ИСТОЧНИКИ И ПРИМЕЧАНИЯ
A44: • Выкуп по $229.50/акция, имплайд $400–450 млрд: китайские деловые СМИ, 15.04.2026
A45: • Вторичный рынок: $550 млрд (Reuters, февраль 2026), биды выше $600 млрд к апрелю 2026
A46: • Выручка 2025 ~$186 млрд (+20%): eMarketer, Bloomberg; капзатраты на ИИ в 2026 — около $70 млрд
...

Sheet Glean
A1: Glean
A2: Корпоративный ИИ-поиск
A4: 1. ЦЕНА
A5: Последний закрытый раунд | B5: Series F $150 млн, закрыт 10.06.2025; лид Wellington Management
A6: Оценка по последнему раунду, $ млрд | B6: 7.2
A7: База для вторичного рынка, $ млрд | B7: 7.2
A8: Премия к базе — нижняя граница | B8: 0.08
A9: Премия к базе — верхняя граница | B9: 0.15
A10: Цена на вторичном рынке — низ, $ млрд | B10: 6.5
A11: Цена на вторичном рынке — верх, $ млрд | B11: 7
A12: Цена входа в расчётах (середина диапазона), $ млрд | B12: =AVERAGE(B10:B11) -> 6.75
A13: Примечание | B13: Диапазон — фактические котировки вторичного рынка. Вторичные сделки идут по $44–47 за акцию против $49.09 в Series F — дисконт около 10% к раунду.
A15: 2. ПУБЛИЧНЫЕ АНАЛОГИ
A16: Компания | B16: Мультипликатор, x | C16: Комментарий
A17: Palantir | B17: 61 | C17: верх диапазона корпоративного софта
A18: Snowflake | B18: 21.3 | C18: EV/Revenue
A19: Datadog | B19: 20.9 | C19: EV/Revenue
A20: MongoDB | B20: 9.5 | C20: EV/Revenue
A21: ServiceNow | B21: 8.2 | C21: EV/Revenue — после падения мультипликаторов в 2026
A23: 3. МЕТОД 1 — МУЛЬТИПЛИКАТОРЫ ВЫРУЧКИ
A24: Сценарий | B24: Год выхода | C24: Лет до выхода | D24: Выручка на выходе, $ млрд | E24: EV/Revenue, x | F24: Оценка на выходе, $ млрд | G24: MOIC, x | H24: Upside, % | I24: IRR, %
A25: Консервативный | B25: 2028 | C25: 2 | D25: 0.6 | E25: 12 | F25: =D25*E25 -> 7.2 | G25: =F25/B12 -> 1.0666667 | H25: =G25-1 -> 0.066666667 | I25: =G25^(1/C25)-1 -> 0.032795559
A26: Базовый | B26: 2029 | C26: 2.5 | D26: 0.9 | E26: 20 | F26: =D26*E26 -> 18 | G26: =F26/B12 -> 2.6666667 | H26: =G26-1 -> 1.6666667 | I26: =G26^(1/C26)-1 -> 0.48042869
A27: Оптимистичный | B27: 2030 | C27: 3.5 | D27: 1.5 | E27: 25 | F27: =D27*E27 -> 37.5 | G27: =F27/B12 -> 5.5555556 | H27: =G27-1 -> 4.5555556 | I27: =G27^(1/C27)-1 -> 0.63222221
A28: ARR превысил $300 млн (май 2026), рост 89% г/г — утроение за 15 месяцев ($100 млн в начале 2025 → $200 млн в декабре → $300 млн в мае). Триггер для IPO аналитики видят на $500 млн — $1 млрд ARR.
A30: 4. МЕТОД 2 — РЫНОЧНЫЕ ЯКОРЯ
A31: Сценарий | B31: Год выхода | C31: Лет до выхода | D31: Якорь оценки | E31: Оценка на выходе, $ млрд | F31: MOIC, x | G31: Upside, % | H31: IRR, %
A32: Консервативный | B32: 2028 | C32: 2 | D32: Продажа стратегу по нижней границе (прецедент: Workday купил Sana за $1.1 млрд) | E32: 10 | F32: =E32/B12 -> 1.4814815 | G32: =F32-1 -> 0.48148148 | H32: =F32^(1/C32)-1 -> 0.21716124
A33: Базовый | B33: 2029 | C33: 2.5 | D33: IPO 2028 в диапазоне $15–20 млрд | E33: 18 | F33: =E33/B12 -> 2.6666667 | G33: =F33-1 -> 1.6666667 | H33: =F33^(1/C33)-1 -> 0.48042869
A34: Оптимистичный | B34: 2030 | C34: 3.5 | D34: Лидер категории корпоративного ИИ-поиска | E34: 30 | F34: =E34/B12 -> 4.4444444 | G34: =F34-1 -> 3.4444444 | H34: =F34^(1/C34)-1 -> 0.53140729
A35: 5. ИТОГ — БАЗОВЫЙ СЦЕНАРИЙ
A36: Оценка на выходе (среднее 2 методов), $ млрд | B36: =AVERAGE(F26,E33) -> 18
A37: MOIC (базовый) | B37: =B36/B12 -> 2.6666667
A38: Upside (базовый) | B38: =B37-1 -> 1.6666667
A39: Доходность инвестора, IRR (базовый) | B39: =B37^(1/C26)-1 -> 0.48042869
A40: Диапазон MOIC (мин. — макс. по всем сценариям) | B40: =MIN(G25,F32) -> 1.0666667 | C40: =MAX(G27,F34) -> 5.5555556
A41: Справочно: MOIC от верхней границы вторичного рынка | B41: =B36/B11 -> 2.5714286
A43: ИСТОЧНИКИ И ПРИМЕЧАНИЯ
A44: • Series F $150 млн @ $7.2 млрд: 10.06.2025, лид Wellington Management; раунда 2026 года нет
A45: • ARR >$300 млн (28.05.2026), +89% г/г; более 1 млн пользователей; всего привлечено ~$765 млн
...

Sheet Lightmatter
A1: Lightmatter
A2: Фотоника для ИИ-дата-центров
A4: 1. ЦЕНА
A5: Последний закрытый раунд | B5: Series D $400 млн, закрыт в октябре 2024; лид T. Rowe Price (Fidelity, GV, Viking Global, Lockheed Martin)
A6: Оценка по последнему раунду, $ млрд | B6: 4.4
A7: База для вторичного рынка, $ млрд | B7: 4.4
A8: Премия к базе — нижняя граница | B8: 0.08
A9: Премия к базе — верхняя граница | B9: 0.15
A10: Цена на вторичном рынке — низ, $ млрд | B10: 4.4
A11: Цена на вторичном рынке — верх, $ млрд | B11: 4.8
A12: Цена входа в расчётах (середина диапазона), $ млрд | B12: =AVERAGE(B10:B11) -> 4.6
A13: Примечание | B13: Диапазон — фактические котировки вторичного рынка. Вторичный рынок оценивает компанию примерно в $4.6 млрд (Forge $84.48, Hiive $89.53 за акцию, 21.08.2026) — вблизи оценки Series D двухлетней давности.
A15: 2. ПУБЛИЧНЫЕ АНАЛОГИ
A16: Компания | B16: Мультипликатор, x | C16: Комментарий
A17: Lumentum | B17: 21.1 | C17: оптические компоненты
A18: NVIDIA | B18: 20.6 | C18: EV/Revenue
A19: Broadcom | B19: 14.2 | C19: NTM EV/Revenue
A20: Coherent | B20: 10.3 | C20: оптика
A21: Marvell | B21: 9.4 | C21: NTM EV/Revenue
A23: 3. МЕТОД 1 — МУЛЬТИПЛИКАТОРЫ ВЫРУЧКИ
A24: Сценарий | B24: Год выхода | C24: Лет до выхода | D24: Выручка на выходе, $ млрд | E24: EV/Revenue, x | F24: Оценка на выходе, $ млрд | G24: MOIC, x | H24: Upside, % | I24: IRR, %
A25: Консервативный | B25: 2029 | C25: 3 | D25: 0.4 | E25: 10 | F25: =D25*E25 -> 4 | G25: =F25/B12 -> 0.86956522 | H25: =G25-1 -> -0.13043478 | I25: =G25^(1/C25)-1 -> -0.045518783
A26: Базовый | B26: 2030 | C26: 3.5 | D26: 1 | E26: 14 | F26: =D26*E26 -> 14 | G26: =F26/B12 -> 3.0434783 | H26: =G26-1 -> 2.0434783 | I26: =G26^(1/C26)-1 -> 0.37437666
A27: Оптимистичный | B27: 2031 | C27: 4.5 | D27: 2.5 | E27: 18 | F27: =D27*E27 -> 45 | G27: =F27/B12 -> 9.7826087 | H27: =G27-1 -> 8.7826087 | I27: =G27^(1/C27)-1 -> 0.65997306
A28: Выручка не раскрывается. Ставка на переход отрасли к оптическим соединениям между чипами: рынок оптики для ИИ-дата-центров растёт с $13.7 млрд (2024) до прогнозных $144 млрд к 2030 году.
A30: 4. МЕТОД 2 — РЫНОЧНЫЕ ЯКОРЯ
A31: Сценарий | B31: Год выхода | C31: Лет до выхода | D31: Якорь оценки | E31: Оценка на выходе, $ млрд | F31: MOIC, x | G31: Upside, % | H31: IRR, %
A32: Консервативный | B32: 2029 | C32: 3 | D32: Продажа стратегу по прецеденту Celestial AI (Marvell, $3.25 млрд + earnout) | E32: 5.5 | F32: =E32/B12 -> 1.1956522 | G32: =F32-1 -> 0.19565217 | H32: =F32^(1/C32)-1 -> 0.061373612
A33: Базовый | B33: 2030 | C33: 3.5 | D33: IPO или продажа стратегу при выходе технологии в серию | E33: 14 | F33: =E33/B12 -> 3.0434783 | G33: =F33-1 -> 2.0434783 | H33: =F33^(1/C33)-1 -> 0.37437666
A34: Оптимистичный | B34: 2031 | C34: 4.5 | D34: Стандарт отрасли по оптическим соединениям | E34: 35 | F34: =E34/B12 -> 7.6086957 | G34: =F34-1 -> 6.6086957 | H34: =F34^(1/C34)-1 -> 0.56980864
A35: 5. ИТОГ — БАЗОВЫЙ СЦЕНАРИЙ
A36: Оценка на выходе (среднее 2 методов), $ млрд | B36: =AVERAGE(F26,E33) -> 14
A37: MOIC (базовый) | B37: =B36/B12 -> 3.0434783
A38: Upside (базовый) | B38: =B37-1 -> 2.0434783
A39: Доходность инвестора, IRR (базовый) | B39: =B37^(1/C26)-1 -> 0.37437666
A40: Диапазон MOIC (мин. — макс. по всем сценариям) | B40: =MIN(G25,F32) -> 0.86956522 | C40: =MAX(G27,F34) -> 9.7826087
A41: Справочно: MOIC от верхней границы вторичного рынка | B41: =B36/B11 -> 2.9166667
A43: ИСТОЧНИКИ И ПРИМЕЧАНИЯ
A44: • Series D $400 млн @ $4.4 млрд: октябрь 2024, лид T. Rowe Price; новых раундов нет
A45: • Вторичный рынок ~$4.6 млрд: Forge и Hiive, 21.08.2026; всего привлечено ~$850 млн
...

Sheet PsiQuantum
A1: PsiQuantum
A2: Квантовые вычисления
A4: 1. ЦЕНА
A5: Последний закрытый раунд | B5: Series E $1.0 млрд, объявлен 10.09.2025; лиды BlackRock, Baillie Gifford, Temasek (с NVentures/NVIDIA, QIA, Macquarie)
A6: Оценка по последнему раунду, $ млрд | B6: 7
A7: База для вторичного рынка, $ млрд | B7: 7
A8: Премия к базе — нижняя граница | B8: 0.08
A9: Премия к базе — верхняя граница | B9: 0.15
A10: Цена на вторичном рынке — низ, $ млрд | B10: =B7*(1+B8) -> 7.56
A11: Цена на вторичном рынке — верх, $ млрд | B11: =B7*(1+B9) -> 8.05
A12: Цена входа в расчётах (середина диапазона), $ млрд | B12: =AVERAGE(B10:B11) -> 7.805
A13: Примечание | B13: Диапазон = премия 8–15% к оценке последнего раунда. Биржевых котировок нет; вторичное размещение открыто 12.08.2026. Диапазон рассчитан как премия 8–15% к оценке Series E.
A15: 2. ПУБЛИЧНЫЕ АНАЛОГИ
A16: Компания | B16: Мультипликатор, x | C16: Комментарий
A17: IonQ | B17: 58 | C17: капитализация $16.5 млрд к выручке FY26 $280–290 млн
A18: Rigetti | B18: 200 | C18: капитализация $4.8 млрд к выручке ~$24 млн — премия за ожидания
A19: D-Wave | B19: 157 | C19: капитализация $6.9 млрд к выручке ~$44 млн
A20: Quantinuum | B20: 15.6 | C20: оценка на IPO 04.06.2026, $ млрд
A23: 3. МЕТОД 1 — МУЛЬТИПЛИКАТОРЫ ВЫРУЧКИ
A24: Сценарий | B24: Год выхода | C24: Лет до выхода | D24: Выручка на выходе, $ млрд | E24: EV/Revenue, x | F24: Оценка на выходе, $ млрд | G24: MOIC, x | H24: Upside, % | I24: IRR, %
A25: Консервативный | B25: 2029 | C25: 3.5 | D25: 0.3 | E25: 25 | F25: =D25*E25 -> 7.5 | G25: =F25/B12 -> 0.96092249 | H25: =G25-1 -> -0.039077514 | I25: =G25^(1/C25)-1 -> -0.0113244
A26: Базовый | B26: 2030 | C26: 4.5 | D26: 1 | E26: 30 | F26: =D26*E26 -> 30 | G26: =F26/B12 -> 3.8436899 | H26: =G26-1 -> 2.8436899 | I26: =G26^(1/C26)-1 -> 0.34878919
A27: Оптимистичный | B27: 2031 | C27: 5.5 | D27: 2.5 | E27: 35 | F27: =D27*E27 -> 87.5 | G27: =F27/B12 -> 11.210762 | H27: =G27-1 -> 10.210762 | I27: =G27^(1/C27)-1 -> 0.55182503
A28: Компания до выручки: все поступления — государственные и партнёрские контракты. Одна из двух компаний (вместе с Microsoft) в стадии C программы DARPA QBI. Публичные квантовые компании торгуются по 50–200 годовых выручек — сектор оценивают по ожиданиям, а не по финансам.
A30: 4. МЕТОД 2 — РЫНОЧНЫЕ ЯКОРЯ
A31: Сценарий | B31: Год выхода | C31: Лет до выхода | D31: Якорь оценки | E31: Оценка на выходе, $ млрд | F31: MOIC, x | G31: Upside, % | H31: IRR, %
A32: Консервативный | B32: 2029 | C32: 3.5 | D32: Оценка остаётся вблизи Series E ($8 млрд) | E32: 8 | F32: =E32/B12 -> 1.024984 | G32: =F32-1 -> 0.024983985 | H32: =F32^(1/C32)-1 -> 0.0070754817
A33: Базовый | B33: 2030 | C33: 4.5 | D33: IPO 2029–30 с премией к Quantinuum ($15.6 млрд на листинге в июне 2026) | E33: 30 | F33: =E33/B12 -> 3.8436899 | G33: =F33-1 -> 2.8436899 | H33: =F33^(1/C33)-1 -> 0.34878919
A34: Оптимистичный | B34: 2031 | C34: 5.5 | D34: Первый в мире отказоустойчивый квантовый компьютер выходит в серию | E34: 70 | F34: =E34/B12 -> 8.9686099 | G34: =F34-1 -> 7.9686099 | H34: =F34^(1/C34)-1 -> 0.49012517
A35: 5. ИТОГ — БАЗОВЫЙ СЦЕНАРИЙ
A36: Оценка на выходе (среднее 2 методов), $ млрд | B36: =AVERAGE(F26,E33) -> 30
A37: MOIC (базовый) | B37: =B36/B12 -> 3.8436899
A38: Upside (базовый) | B38: =B37-1 -> 2.8436899
A39: Доходность инвестора, IRR (базовый) | B39: =B37^(1/C26)-1 -> 0.34878919
A40: Диапазон MOIC (мин. — макс. по всем сценариям) | B40: =MIN(G25,F32) -> 0.96092249 | C40: =MAX(G27,F34) -> 11.210762
A41: Справочно: MOIC от верхней границы вторичного рынка | B41: =B36/B11 -> 3.7267081
A43: ИСТОЧНИКИ И ПРИМЕЧАНИЯ
A44: • Series E $1.0 млрд @ $7 млрд: 10.09.2025; лиды BlackRock, Baillie Gifford, Temasek
A45: • Всего мобилизовано ~$3.5–3.7 млрд: ~$2.3 млрд частных + A$940 млн Австралия + >$500 млн Иллинойс + $125 млн DARPA
A46: • Окно выхода открылось: Quantinuum вышел на Nasdaq 04.06.2026, привлёк $1.68 млрд при оценке ~$15.6 млрд
...
